Workbook

Sheet DB Trckg Summary
A1: Ach Oct | B1: =B15/B2 -> 0.14127219 | C1: =C15/C2 -> 0.14127219 | D1: =D15/D2 -> 0.15310651 | E1: =E15/E2 -> 0.18047337
A2: Target Oct | B2: 1352 | C2: 1352 | D2: 1352 | E2: 1352
A3: Salesman Name | B3: Sum of MSS BB | C3: Sum of MSS Dc Inst | D3: Sum of MSS Milo Ton | E3: Sum of MSS Milo UHT | F3: Distinct Count of Outlet[Outlet code]
A4: (blank) | F4: 1
A5: Abdul | B5: 49 | C5: 27 | D5: 41 | E5: 56 | F5: 69
A6: Ajeng | B6: 6 | C6: 5 | D6: 7 | E6: 6 | F6: 7
A7: Akbar Sobirin | B7: 8 | C7: 12 | D7: 9 | E7: 19 | F7: 25
A8: Al Setyah Anggun | B8: 21 | C8: 21 | D8: 22 | E8: 31 | F8: 44
A9: Belum Masuk JP | B9: 1 | C9: 0 | D9: 1 | E9: 1 | F9: 2
A10: Eko Prasetyo | B10: 21 | C10: 18 | D10: 17 | E10: 27 | F10: 41
A11: Fariq | B11: 28 | C11: 33 | D11: 33 | E11: 25 | F11: 53
A12: Supri | B12: 6 | C12: 3 | D12: 2 | E12: 10 | F12: 16
A13: Tuan Suhanda | B13: 25 | C13: 35 | D13: 36 | E13: 25 | F13: 53
A14: Watinah Amalia | B14: 26 | C14: 37 | D14: 39 | E14: 44 | F14: 66
A15: Grand Total | B15: 191 | C15: 191 | D15: 207 | E15: 244 | F15: 377

Sheet DB Tracking by Slsmn
A1: Visit Day | B1: All | H1: Visit Day | I1: All | O1: Visit Day | P1: All | V1: Visit Day | W1: All | AC1: Visit Day | AD1: All | AJ1: Visit Day | AK1: All | AQ1: Visit Day | AR1: All | AX1: Visit Day | AY1: All | BE1: Visit Day | BF1: All | BL1: Visit Day | BM1: All
A2: Salesman Name | B2: Ajeng | H2: Salesman Name | I2: Watinah Amalia | O2: Salesman Name | P2: Tuan Suhanda | V2: Salesman Name | W2: Abdul | AC2: Salesman Name | AD2: Akbar Sobirin | AJ2: Salesman Name | AK2: Supri | AQ2: Salesman Name | AR2: Fariq | AX2: Salesman Name | AY2: Eko Prasetyo | BE2: Salesman Name | BF2: Al Setyah Anggun | BL2: Salesman Name | BM2: Belum Masuk JP
A3: MTS001 - Ajeng | H3: SMC001 - Watinah Amalia | O3: SMC002 - Tuan Suhanda | V3: SMC003 - Abdul | AC3: SMC004 - Akbar Sobirin | AJ3: SMC005 - Supri | AQ3: SMC006 - Fariq | AX3: SMC007 - Eko Prasetyo | BE3: SMC008 - Al Setyah Anggun | BL3: Belum Masuk JP
A4: Outlet[Outlet code] | B4: Outlet[Outlet name] | C4: Sum of MSS BB | D4: Sum of MSS Dc Inst | E4: Sum of MSS Milo Ton | F4: Sum of MSS Milo UHT | H4: Outlet[Outlet code] | I4: Outlet[Outlet name] | J4: Sum of MSS BB | K4: Sum of MSS Dc Inst | L4: Sum of MSS Milo Ton | M4: Sum of MSS Milo UHT | O4: Outlet[Outlet code] | P4: Outlet[Outlet name] | Q4: Sum of MSS BB | R4: Sum of MSS Dc Inst | S4: Sum of MSS Milo Ton | T4: Sum of MSS Milo UHT | V4: Outlet[Outlet code] | W4: Outlet[Outlet name] | X4: Sum of MSS BB | Y4: Sum of MSS Dc Inst | Z4: Sum of MSS Milo Ton | AA4: Sum of MSS Milo UHT | AC4: Outlet[Outlet code] | AD4: Outlet[Outlet name] | AE4: Sum of MSS BB | AF4: Sum of MSS Dc Inst | AG4: Sum of MSS Milo Ton | AH4: Sum of MSS Milo UHT | AJ4: Outlet[Outlet code] | AK4: Outlet[Outlet name] | AL4: Sum of MSS BB | AM4: Sum of MSS Dc Inst | AN4: Sum of MSS Milo Ton | AO4: Sum of MSS Milo UHT | AQ4: Outlet[Outlet code] | AR4: Outlet[Outlet name] | AS4: Sum of MSS BB | AT4: Sum of MSS Dc Inst | AU4: Sum of MSS Milo Ton | AV4: Sum of MSS Milo UHT | AX4: Outlet[Outlet code] | AY4: Outlet[Outlet name] | AZ4: Sum of MSS BB | BA4: Sum of MSS Dc Inst | BB4: Sum of MSS Milo Ton | BC4: Sum of MSS Milo UHT | BE4: Outlet[Outlet code] | BF4: Outlet[Outlet name] | BG4: Sum of MSS BB | BH4: Sum of MSS Dc Inst | BI4: Sum of MSS Milo Ton | BJ4: Sum of MSS Milo UHT | BL4: Outlet[Outlet code] | BM4: Outlet[Outlet name] | BN4: Sum of MSS BB | BO4: Sum of MSS Dc Inst | BP4: Sum of MSS Milo Ton | BQ4: Sum of MSS Milo UHT
A5: 0001887881_16AKXK1026 | B5: CV CNR ANUGERAH UTAMA | C5: 1 | D5: 0 | E5: 1 | F5: 0 | H5: 0001887881_10217 | I5: TOKO AULIA EMPAT | J5: 0 | K5: 0 | L5: 0 | M5: 1 | O5: 0001887881_10056 | P5: TOKO PRIMA JAYA 6 | Q5: 1 | R5: 1 | S5: 0 | T5: 0 | V5: 0001887881_10083 | W5: TOKO NURUL ALFI | X5: 1 | Y5: 0 | Z5: 0 | AA5: 1 | AC5: 0001887881_16AKXF2642 | AD5: TOKO MAJU MANDIRI | AE5: 0 | AF5: 0 | AG5: 0 | AH5: 1 | AJ5: 0001887881_16AOTN1009 | AK5: TK BUDE WAHYU | AL5: 0 | AM5: 0 | AN5: 0 | AO5: 1 | AQ5: 0001887881_10213 | AR5: TOKO DAFFA | AS5: 1 | AT5: 1 | AU5: 1 | AV5: 1 | AX5: 0001887881_16AKXE0005 | AY5: TOKO ANEKA BASMALAH | AZ5: 1 | BA5: 0 | BB5: 0 | BC5: 1 | BE5: 0001887881_16AKXE0012 | BF5: TOKO IRFAN | BG5: 1 | BH5: 0 | BI5: 0 | BJ5: 1 | BL5: 0 | BM5: 0 | BN5: 0 | BO5: 0 | BP5: 0 | BQ5: 0
A6: 0001887881_16AMNN3621 | B6: PT BERKAH BANDUNG OPS | C6: 1 | D6: 1 | E6: 1 | F6: 1 | H6: 0001887881_1523358 | I6: TOKO HAJI DIANA | J6: 1 | K6: 1 | L6: 1 | M6: 1 | O6: 0001887881_10070 | P6: ARIA | Q6: 0 | R6: 1 | S6: 1 | T6: 0 | V6: 0001887881_10200 | W6: Toko Berkah | X6: 1 | Y6: 0 | Z6: 1 | AA6: 1 | AC6: 0001887881_16AKXF4363 | AD6: TOKO FRISKA | AE6: 0 | AF6: 1 | AG6: 0 | AH6: 0 | AJ6: 0001887881_16ARAJ1008 | AK6: TK GAHRU | AL6: 1 | AM6: 0 | AN6: 0 | AO6: 0 | AQ6: 0001887881_16AKWV1008 | AR6: TOKO LARIS TIGA | AS6: 0 | AT6: 1 | AU6: 0 | AV6: 1 | AX6: 0001887881_16AKXE0021 | AY6: TOKO FARAS | AZ6: 1 | BA6: 1 | BB6: 1 | BC6: 1 | BE6: 0001887881_16AKXE0017 | BF6: TOKO DEVEN | BG6: 0 | BH6: 0 | BI6: 0 | BJ6: 1 | BL6: 0001887881_16ASOH1081 | BM6: TOKO DAFFA | BN6: 1 | BO6: 0 | BP6: 1 | BQ6: 1
A7: 0001887881_16ANNK1003 | B7: PT BERKAH BEKASI OPS | C7: 1 | D7: 1 | E7: 1 | F7: 1 | H7: 0001887881_1523377 | I7: TOKO AL AZHAR | J7: 1 | K7: 1 | L7: 1 | M7: 1 | O7: 0001887881_10131 | P7: TOKO Mulia | Q7: 1 | R7: 1 | S7: 0 | T7: 0 | V7: 0001887881_10242 | W7: Toko Baru VIII | X7: 1 | Y7: 0 | Z7: 1 | AA7: 1 | AC7: 0001887881_16AKXJ1025 | AD7: TOKO SEMBAKO MADINAH | AE7: 1 | AF7: 1 | AG7: 0 | AH7: 1 | AJ7: 0001887881_16ARBK1003 | AK7: WR NUSANTARA MART | AL7: 0 | AM7: 0 | AN7: 0 | AO7: 1 | AQ7: 0001887881_16AKWV1045 | AR7: Toko Berkah | AS7: 0 | AT7: 1 | AU7: 1 | AV7: 0 | AX7: 0001887881_16AKXH1024 | AY7: TOKO MAMANG | AZ7: 1 | BA7: 0 | BB7: 1 | BC7: 1 | BE7: 0001887881_16AKXE0038 | BF7: TOKO ANISSA PLASTIK | BG7: 0 | BH7: 1 | BI7: 1 | BJ7: 1 | BL7: Grand Total | BN7: 1 | BO7: 0 | BP7: 1 | BQ7: 1
A8: 0001887881_16AOJC1001 | B8: PT. BERKAH KARAWANG OPS | C8: 1 | D8: 1 | E8: 1 | F8: 1 | H8: 0001887881_1523378 | I8: TOKO KORBI STORE | J8: 0 | K8: 0 | L8: 0 | M8: 1 | O8: 0001887881_10311 | P8: Terang Jaya | Q8: 0 | R8: 0 | S8: 1 | T8: 1 | V8: 0001887881_16AKWV1009 | W8: toko eno | X8: 1 | Y8: 1 | Z8: 1 | AA8: 1 | AC8: 0001887881_16AKXJ2156 | AD8: TOKO MD HAFIZ | AE8: 0 | AF8: 0 | AG8: 0 | AH8: 1 | AJ8: 0001887881_16ARBK1005 | AK8: WR HANJUANG | AL8: 0 | AM8: 0 | AN8: 0 | AO8: 1 | AQ8: 0001887881_16AKWV1048 | AR8: Toko Saidah | AS8: 1 | AT8: 0 | AU8: 1 | AV8: 1 | AX8: 0001887881_16AKXJ1004 | AY8: TOKO SUMBER JATI MULYO | AZ8: 1 | BA8: 1 | BB8: 0 | BC8: 1 | BE8: 0001887881_16AKXJ1011 | BF8: TOKO RAHAYU 2 | BG8: 1 | BH8: 1 | BI8: 1 | BJ8: 1
A9: 0001887881_16APFP1068 | B9: TOKO PANJI | C9: 0 | D9: 0 | E9: 1 | F9: 1 | H9: 0001887881_16AKRT1003 | I9: TOKO FB MULYA SEJAHTERA | J9: 0 | K9: 0 | L9: 1 | M9: 1 | O9: 0001887881_10327 | P9: TOKO PARMAN | Q9: 0 | R9: 1 | S9: 0 | T9: 1 | V9: 0001887881_16AKWV1051 | W9: TOKO DODIT | X9: 1 | Y9: 0 | Z9: 0 | AA9: 1 | AC9: 0001887881_16AKXK3095 | AD9: toko fandy grosir | AE9: 0 | AF9: 1 | AG9: 1 | AH9: 1 | AJ9: 0001887881_16ARBN1005 | AK9: TK MANDIRI 2 | AL9: 1 | AM9: 0 | AN9: 0 | AO9: 0 | AQ9: 0001887881_16AKWV1052 | AR9: TOKO CERMAI | AS9: 1 | AT9: 0 | AU9: 0 | AV9: 1 | AX9: 0001887881_16AKXL1007 | AY9: TOKO UJANG | AZ9: 1 | BA9: 1 | BB9: 1 | BC9: 1 | BE9: 0001887881_16AKXJ1024 | BF9: TOKO INDAH | BG9: 1 | BH9: 1 | BI9: 1 | BJ9: 0
A10: 0001887881_16ASOD1060 | B10: PT BERKAH TANGGERANG OPS | C10: 1 | D10: 1 | E10: 1 | F10: 1 | H10: 0001887881_16AKRT1007 | I10: TOKO APOTIK AYAH | J10: 1 | K10: 0 | L10: 0 | M10: 1 | O10: 0001887881_10392 | P10: TOKO ALJABAL | Q10: 1 | R10: 0 | S10: 0 | T10: 1 | V10: 0001887881_16AKWY1004 | W10: TOKO ROPIKOH | X10: 1 | Y10: 1 | Z10: 1 | AA10: 1 | AC10: 0001887881_16ALXG1003 | AD10: TOKO AMINAH BERKAH | AE10: 0 | AF10: 0 | AG10: 0 | AH10: 1 | AJ10: 0001887881_16ARBN1006 | AK10: WARUNG BASRI FAHRI | AL10: 1 | AM10: 0 | AN10: 0 | AO10: 0 | AQ10: 0001887881_16AKWV3646 | AR10: Toko Tamaguna | AS10: 1 | AT10: 0 | AU10: 0 | AV10: 1 | AX10: 0001887881_16ALXL1002 | AY10: TOKO BERKAT PLASTIK | AZ10: 1 | BA10: 0 | BB10: 0 | BC10: 1 | BE10: 0001887881_16AKXL1005 | BF10: TOKO MITRA ANDA | BG10: 0 | BH10: 1 | BI10: 1 | BJ10: 0
A11: 0001887881_16ASTF1038 | B11: PT BERKAH DEPOK OPS | C11: 1 | D11: 1 | E11: 1 | F11: 1 | H11: 0001887881_16AKRT1010 | I11: TOKO ELSA TARUMAJAYA | J11: 1 | K11: 0 | L11: 1 | M11: 1 | O11: 0001887881_161012 | P11: Toko Dini (psMGT) | Q11: 0 | R11: 1 | S11: 0 | T11: 0 | V11: 0001887881_16ALWY1002 | W11: TOKO AYU | X11: 1 | Y11: 0 | Z11: 1 | AA11: 1 | AC11: 0001887881_16ALXG1006 | AD11: TOKO MAJALENGKA TIGA | AE11: 1 | AF11: 0 | AG11: 0 | AH11: 0 | AJ11: 0001887881_16ARBO1025 | AK11: TK DIDI | AL11: 0 | AM11: 0 | AN11: 0 | AO11: 1 | AQ11: 0001887881_16AKWV3648 | AR11: Toko Surya Mart | AS11: 1 | AT11: 0 | AU11: 0 | AV11: 1 | AX11: 0001887881_16ALXL1004 | AY11: TOKO KAKA ADIK | AZ11: 0 | BA11: 1 | BB11: 1 | BC11: 0 | BE11: 0001887881_16ALHP1001 | BF11: TOKO AZKA DN | BG11: 1 | BH11: 1 | BI11: 1 | BJ11: 1
A12: Grand Total | C12: 6 | D12: 5 | E12: 7 | F12: 6 | H12: 0001887881_16AKRX1004 | I12: TOKO KEKE FROZEN | J12: 0 | K12: 0 | L12: 1 | M12: 1 | O12: 0001887881_16AKXC1010 | P12: Toko Rizky Jaya | Q12: 0 | R12: 1 | S12: 1 | T12: 0 | V12: 0001887881_16ALWY1030 | W12: TOKO RIYA MART | X12: 0 | Y12: 0 | Z12: 0 | AA12: 1 | AC12: 0001887881_16ALXG1007 | AD12: TOKO SUMBER REJEKI DOEA | AE12: 0 | AF12: 0 | AG12: 0 | AH12: 1 | AJ12: 0001887881_16ARRL1028 | AK12: TK NAZILA SATU | AL12: 0 | AM12: 0 | AN12: 0 | AO12: 1 | AQ12: 0001887881_16AKXD1004 | AR12: TOKO BERSAMA | AS12: 1 | AT12: 0 | AU12: 1 | AV12: 1 | AX12: 0001887881_16ALXL1005 | AY12: TOKO SALWA 46 | AZ12: 1 | BA12: 0 | BB12: 0 | BC12: 1 | BE12: 0001887881_16ALWO0007 | BF12: TOKO KARLOS | BG12: 1 | BH12: 0 | BI12: 0 | BJ12: 1
H13: 0001887881_16AKRZ1004 | I13: ALMIRA JAYA MANDIRI | J13: 0 | K13: 0 | L13: 1 | M13: 1 | O13: 0001887881_16AKXK1027 | P13: PT RAUDAH SUFINDO INT | Q13: 1 | R13: 1 | S13: 0 | T13: 0 | V13: 0001887881_16ALWY1048 | W13: Toko Riska | X13: 0 | Y13: 0 | Z13: 0 | AA13: 1 | AC13: 0001887881_16ANLW4371 | AD13: TOKO FREYA | AE13: 0 | AF13: 1 | AG13: 1 | AH13: 1 | AJ13: 0001887881_16ARRN4267 | AK13: TK ANTARIKSA DUA | AL13: 0 | AM13: 1 | AN13: 0 | AO13: 1 | AQ13: 0001887881_16ALWO1005 | AR13: TOKO AMIN ILYAS | AS13: 1 | AT13: 1 | AU13: 0 | AV13: 0 | AX13: 0001887881_16ALXL1006 | AY13: TOKO JAKY | AZ13: 0 | BA13: 0 | BB13: 0 | BC13: 1 | BE13: 0001887881_16ALWO0010 | BF13: TOKO NAILA | BG13: 1 | BH13: 0 | BI13: 0 | BJ13: 1
H14: 0001887881_16AKWU1003 | I14: Toko Makmur Sentosa | J14: 1 | K14: 1 | L14: 1 | M14: 0 | O14: 0001887881_16ALWQ1002 | P14: TOKO HARAPAN BARU | Q14: 0 | R14: 1 | S14: 1 | T14: 1 | V14: 0001887881_16ALWY1064 | W14: TOKO SEMBAKO ALDI NASUTION | X14: 0 | Y14: 0 | Z14: 0 | AA14: 1 | AC14: 0001887881_16ANLY1025 | AD14: TOKO EKI | AE14: 0 | AF14: 0 | AG14: 0 | AH14: 1 | AJ14: 0001887881_16ARRN4268 | AK14: TK LARIS YUMNA | AL14: 1 | AM14: 0 | AN14: 0 | AO14: 0 | AQ14: 0001887881_16AMDO1004 | AR14: TOKO AKWANG | AS14: 0 | AT14: 1 | AU14: 0 | AV14: 1 | AX14: 0001887881_16ALXL1007 | AY14: toko martin | AZ14: 1 | BA14: 0 | BB14: 0 | BC14: 1 | BE14: 0001887881_16ALWO0012 | BF14: TOKO RJ | BG14: 0 | BH14: 0 | BI14: 0 | BJ14: 1
H15: 0001887881_16AKWV1003 | I15: Toko Simas | J15: 1 | K15: 1 | L15: 1 | M15: 1 | O15: 0001887881_16ALWQ1006 | P15: TOKO DEVEN | Q15: 0 | R15: 1 | S15: 1 | T15: 0 | V15: 0001887881_16AMKM1067 | W15: TOKO MS | X15: 1 | Y15: 0 | Z15: 0 | AA15: 1 | AC15: 0001887881_16ARAW1025 | AD15: TOKO BERKAH TCI | AE15: 0 | AF15: 0 | AG15: 0 | AH15: 1 | AJ15: 0001887881_16ARRN4270 | AK15: TK MJ CIAMIS | AL15: 1 | AM15: 0 | AN15: 0 | AO15: 0 | AQ15: 0001887881_16AMDQ1007 | AR15: TOKO SUDIRMAN | AS15: 1 | AT15: 1 | AU15: 1 | AV15: 0 | AX15: 0001887881_16ALXL1008 | AY15: TOKO BUNGA BERKAH | AZ15: 0 | BA15: 1 | BB15: 1 | BC15: 0 | BE15: 0001887881_16ALWO0013 | BF15: TOKO JASMIN 2 | BG15: 1 | BH15: 1 | BI15: 0 | BJ15: 1
H16: 0001887881_16AKWV1005 | I16: TOKO MENARA DUA GROSIR | J16: 0 | K16: 1 | L16: 1 | M16: 0 | O16: 0001887881_16ALWU0001 | P16: TOKO 3 SAUDARA MART | Q16: 1 | R16: 0 | S16: 1 | T16: 1 | V16: 0001887881_16AMKM1082 | W16: Toko Nurul | X16: 1 | Y16: 1 | Z16: 1 | AA16: 0 | AC16: 0001887881_16ARRK1001 | AD16: TOKO ADIRASYA | AE16: 0 | AF16: 1 | AG16: 0 | AH16: 1 | AJ16: 0001887881_16ARRN4271 | AK16: TK DUA PUTRI | AL16: 0 | AM16: 0 | AN16: 0 | AO16: 1 | AQ16: 0001887881_16AMKJ1001 | AR16: TOKO PUTRA | AS16: 1 | AT16: 1 | AU16: 1 | AV16: 0 | AX16: 0001887881_16ALXM1001 | AY16: TOKO SUMBER URIP 2 | AZ16: 1 | BA16: 0 | BB16: 1 | BC16: 1 | BE16: 0001887881_16ALXM1436 | BF16: TOKO IMAN | BG16: 1 | BH16: 1 | BI16: 0 | BJ16: 1
H17: 0001887881_16AKWX1005 | I17: TOKO SEMBAKO AL BAROKAH EMPAT | J17: 0 | K17: 1 | L17: 1 | M17: 0 | O17: 0001887881_16ANLW1037 | P17: TOKO DENDRI I | Q17: 0 | R17: 0 | S17: 1 | T17: 0 | V17: 0001887881_16AMKM1085 | W17: TOKO HIKMAH PLASTIK | X17: 1 | Y17: 0 | Z17: 0 | AA17: 1 | AC17: 0001887881_16ARRN1013 | AD17: TOKO FADILAH | AE17: 0 | AF17: 1 | AG17: 1 | AH17: 1 | AJ17: 0001887881_16ARRN4275 | AK17: TOKO ASONAR MART | AL17: 0 | AM17: 0 | AN17: 0 | AO17: 1 | AQ17: 0001887881_16AMKJ1063 | AR17: TOKO ANUGRAH JAYA SNACK | AS17: 0 | AT17: 1 | AU17: 1 | AV17: 0 | AX17: 0001887881_16ALXM1006 | AY17: TOKO RAFDAN | AZ17: 0 | BA17: 1 | BB17: 0 | BC17: 1 | BE17: 0001887881_16AOTL1001 | BF17: Sutan JS | BG17: 0 | BH17: 1 | BI17: 1 | BJ17: 0
H18: 0001887881_16AKWY1008 | I18: TOKO WIWIN | J18: 0 | K18: 0 | L18: 0 | M18: 1 | O18: 0001887881_16ANLW1038 | P18: HASNA HASNI | Q18: 0 | R18: 0 | S18: 1 | T18: 1 | V18: 0001887881_16AMKN1075 | W18: TOKO RIFKI | X18: 1 | Y18: 1 | Z18: 1 | AA18: 1 | AC18: 0001887881_16ARRN1014 | AD18: TOKO BAROKAH AUREL SATU | AE18: 0 | AF18: 0 | AG18: 0 | AH18: 1 | AJ18: 0001887881_16ARRO1329 | AK18: WARUNG 2S | AL18: 1 | AM18: 1 | AN18: 0 | AO18: 0 | AQ18: 0001887881_16AMKL1003 | AR18: TOKO MAJU JAYA SNACK | AS18: 1 | AT18: 1 | AU18: 1 | AV18: 0 | AX18: 0001887881_16ARAC1002 | AY18: TOKO FITRI | AZ18: 1 | BA18: 1 | BB18: 1 | BC18: 1 | BE18: 0001887881_16AOTN1001 | BF18: Toko sumber rejeki | BG18: 1 | BH18: 1 | BI18: 1 | BJ18: 1
H19: 0001887881_16AKXE1006 | I19: TOKO MAS JOKO | J19: 0 | K19: 0 | L19: 0 | M19: 1 | O19: 0001887881_16ANLW1050 | P19: TOKO HARAPAN BARU I | Q19: 1 | R19: 1 | S19: 1 | T19: 1 | V19: 0001887881_16AMKN1091 | W19: toko deny | X19: 0 | Y19: 1 | Z19: 1 | AA19: 0 | AC19: 0001887881_16ARRN1015 | AD19: TOKO BAGAS | AE19: 0 | AF19: 1 | AG19: 1 | AH19: 1 | AJ19: 0001887881_16ARRO1332 | AK19: Tk barokah madura | AL19: 0 | AM19: 1 | AN19: 1 | AO19: 1 | AQ19: 0001887881_16AMKM1010 | AR19: TOKO IRZA | AS19: 1 | AT19: 0 | AU19: 0 | AV19: 0 | AX19: 0001887881_16ARAC1003 | AY19: TOKO BERKAH MANDIRI | AZ19: 0 | BA19: 1 | BB19: 0 | BC19: 0 | BE19: 0001887881_16AOTS1001 | BF19: TOKO HANI | BG19: 1 | BH19: 1 | BI19: 1 | BJ19: 0
H20: 0001887881_16AKXI1003 | I20: TOKO ZIDAN TIGA | J20: 1 | K20: 1 | L20: 1 | M20: 1 | O20: 0001887881_16ANNL1006 | P20: TOKO ADIN | Q20: 0 | R20: 0 | S20: 0 | T20: 1 | V20: 0001887881_16AMKN1094 | W20: TOKO ARSYILA BABY SHOP | X20: 1 | Y20: 0 | Z20: 1 | AA20: 1 | AC20: 0001887881_16ARRN4263 | AD20: TOKO M FATIR | AE20: 1 | AF20: 0 | AG20: 0 | AH20: 1 | AJ20: 0001887881_16ARRO1334 | AK20: TK RIFKI | AL20: 0 | AM20: 0 | AN20: 1 | AO20: 1 | AQ20: 0001887881_16AMKM1020 | AR20: TOKO LARIS SNACK | AS20: 0 | AT20: 1 | AU20: 1 | AV20: 0 | AX20: 0001887881_16ARAC1012 | AY20: TOKO ALFINO | AZ20: 0 | BA20: 0 | BB20: 0 | BC20: 1 | BE20: 0001887881_16ARAA1001 | BF20: TOKO UDIN | BG20: 0 | BH20: 1 | BI20: 0 | BJ20: 1
H21: 0001887881_16ALWO1009 | I21: Toko Sanjaya | J21: 1 | K21: 0 | L21: 1 | M21: 1 | O21: 0001887881_16APFR1013 | P21: Sogi grosir | Q21: 0 | R21: 0 | S21: 1 | T21: 1 | V21: 0001887881_16AMKN1110 | W21: TOKO JUNAEDI | X21: 1 | Y21: 0 | Z21: 1 | AA21: 1 | AC21: 0001887881_16ARRN4264 | AD21: TOKO KEBUMEN JAYA | AE21: 0 | AF21: 0 | AG21: 1 | AH21: 1 | AJ21: Grand Total | AL21: 6 | AM21: 3 | AN21: 2 | AO21: 10 | AQ21: 0001887881_16AMKM1047 | AR21: TOKO LAILA FROZEN | AS21: 0 | AT21: 1 | AU21: 1 | AV21: 0 | AX21: 0001887881_16ARAD1011 | AY21: TOKO PAK DE JUM | AZ21: 0 | BA21: 0 | BB21: 0 | BC21: 0 | BE21: 0001887881_16ARAD1500 | BF21: Debora | BG21: 0 | BH21: 0 | BI21: 0 | BJ21: 1
H22: 0001887881_16ALWO1015 | I22: TOKO MADURA BINTANG ARIS | J22: 0 | K22: 0 | L22: 0 | M22: 1 | O22: 0001887881_16ASNO1007 | P22: TOKO KURNIA | Q22: 1 | R22: 1 | S22: 1 | T22: 0 | V22: 0001887881_16AMKN1113 | W22: TOKO HAIKAL | X22: 0 | Y22: 0 | Z22: 1 | AA22: 1 | AC22: 0001887881_16ARRO1314 | AD22: toko rani mandiri | AE22: 0 | AF22: 1 | AG22: 0 | AH22: 0 | AQ22: 0001887881_16AMKM1050 | AR22: TOKO PURBA | AS22: 1 | AT22: 0 | AU22: 0 | AV22: 1 | AX22: 0001887881_16ARAD1498 | AY22: TOKO SEPTIANA | AZ22: 1 | BA22: 0 | BB22: 0 | BC22: 0 | BE22: 0001887881_16ARAE1003 | BF22: TOKO ENI 2 | BG22: 0 | BH22: 0 | BI22: 0 | BJ22: 1
H23: 0001887881_16ALWO1022 | I23: CV BAROKAH BERSAMA WARGA | J23: 0 | K23: 1 | L23: 0 | M23: 0 | O23: 0001887881_16ASNQ1007 | P23: TOKO AFRAN | Q23: 0 | R23: 1 | S23: 1 | T23: 0 | V23: 0001887881_16AMKQ1048 | W23: TOKO DANDY | X23: 1 | Y23: 1 | Z23: 1 | AA23: 1 | AC23: 0001887881_16ARRO1315 | AD23: toko aisyah | AE23: 1 | AF23: 1 | AG23: 1 | AH23: 0 | AQ23: 0001887881_16AMKN1027 | AR23: Toko Lia | AS23: 1 | AT23: 0 | AU23: 0 | AV23: 0 | AX23: 0001887881_16ARAV1003 | AY23: Toko Akbar Jaya | AZ23: 1 | BA23: 1 | BB23: 1 | BC23: 1 | BE23: 0001887881_16ARAE1005 | BF23: TOKO MELVISA | BG23: 1 | BH23: 0 | BI23: 0 | BJ23: 1
H24: 0001887881_16ALWO1023 | I24: Toko Ishak | J24: 1 | K24: 0 | L24: 0 | M24: 1 | O24: 0001887881_16ASNQ1008 | P24: TOKO SIMANALAGI | Q24: 1 | R24: 1 | S24: 1 | T24: 0 | V24: 0001887881_16AMKQ1055 | W24: TOKO HASAN | X24: 1 | Y24: 0 | Z24: 1 | AA24: 1 | AC24: 0001887881_16ARRO1323 | AD24: TOKO BERKAH JAYA PLASTIK | AE24: 0 | AF24: 0 | AG24: 1 | AH24: 1 | AQ24: 0001887881_16AMKN1153 | AR24: Toko SUMBER REZEKI | AS24: 0 | AT24: 0 | AU24: 1 | AV24: 1 | AX24: 0001887881_16ARAV1010 | AY24: TOKO FATAN | AZ24: 0 | BA24: 0 | BB24: 0 | BC24: 1 | BE24: 0001887881_16ARAG1001 | BF24: TOKO JAYA BERKAH PLASTIK | BG24: 0 | BH24: 1 | BI24: 1 | BJ24: 0
H25: 0001887881_16ALWY4318 | I25: TOKO AJA | J25: 1 | K25: 0 | L25: 0 | M25: 1 | O25: 0001887881_16ASNS1022 | P25: TOKO JAYA BAROKAH KUNINGAN | Q25: 0 | R25: 1 | S25: 1 | T25: 0 | V25: 0001887881_16ANLV0001 | W25: Toko dua empat | X25: 0 | Y25: 0 | Z25: 0 | AA25: 1 | AC25: 0001887881_16ASNZ8599 | AD25: TOKO BANG MAEL | AE25: 1 | AF25: 0 | AG25: 0 | AH25: 0 | AQ25: 0001887881_16AMKO1011 | AR25: TOKO ANGGA | AS25: 1 | AT25: 1 | AU25: 0 | AV25: 1 | AX25: 0001887881_16ARBA1001 | AY25: TOKO AM | AZ25: 1 | BA25: 1 | BB25: 1 | BC25: 0 | BE25: 0001887881_16ARAL1004 | BF25: teh nde | BG25: 0 | BH25: 0 | BI25: 0 | BJ25: 1
H26: 0001887881_16AMDQ1015 | I26: TOKO RAFA | J26: 0 | K26: 1 | L26: 1 | M26: 0 | O26: 0001887881_16ASNU1009 | P26: TOKO JAWA PLASTIK DUA | Q26: 0 | R26: 1 | S26: 1 | T26: 0 | V26: 0001887881_16ANLV1005 | W26: TOKO CAHAYA BERKAH | X26: 1 | Y26: 0 | Z26: 1 | AA26: 1 | AC26: 0001887881_16ASTF1042 | AD26: TOKO RAZO | AE26: 1 | AF26: 1 | AG26: 1 | AH26: 1 | AQ26: 0001887881_16AMKO1017 | AR26: TOKO RATNA | AS26: 1 | AT26: 1 | AU26: 0 | AV26: 1 | AX26: 0001887881_16ARBA1002 | AY26: TOKO BAHRI | AZ26: 1 | BA26: 0 | BB26: 1 | BC26: 0 | BE26: 0001887881_16ARAN1003 | BF26: TOKO IHSAN | BG26: 0 | BH26: 0 | BI26: 1 | BJ26: 0
H27: 0001887881_16AMDR0004 | I27: TOKO ALDI KABAN DUA | J27: 1 | K27: 1 | L27: 1 | M27: 1 | O27: 0001887881_16ASNW0020 | P27: TOKO YULI | Q27: 1 | R27: 1 | S27: 1 | T27: 0 | V27: 0001887881_16ANLV1012 | W27: TOKO TBK FORTUNA | X27: 1 | Y27: 0 | Z27: 1 | AA27: 1 | AC27: 0001887881_16ASTG1009 | AD27: TOKO PERMATA RUDY | AE27: 0 | AF27: 0 | AG27: 0 | AH27: 1 | AQ27: 0001887881_16AMKQ1006 | AR27: TOKO TRIJAYA | AS27: 0 | AT27: 0 | AU27: 1 | AV27: 1 | AX27: 0001887881_16ARBB1005 | AY27: TOKO SEGAR SAYUR | AZ27: 0 | BA27: 1 | BB27: 0 | BC27: 0 | BE27: 0001887881_16ARAQ1002 | BF27: Toko akbar | BG27: 1 | BH27: 0 | BI27: 1 | BJ27: 1
H28: 0001887881_16AMKL0012 | I28: TOKO AWI PEJUANG | J28: 0 | K28: 1 | L28: 1 | M28: 1 | O28: 0001887881_16ASNZ1004 | P28: TOKO ANGGI | Q28: 1 | R28: 0 | S28: 0 | T28: 1 | V28: 0001887881_16ANLW1052 | W28: CAHAYA WULAN | X28: 1 | Y28: 0 | Z28: 1 | AA28: 1 | AC28: 0001887881_1766521 | AD28: TOKO RIE RIE | AE28: 1 | AF28: 1 | AG28: 1 | AH28: 1 | AQ28: 0001887881_16AMKQ1073 | AR28: TOKO ASPAR JAYA | AS28: 0 | AT28: 1 | AU28: 1 | AV28: 0 | AX28: 0001887881_16ARBE1002 | AY28: toko dewi | AZ28: 1 | BA28: 0 | BB28: 1 | BC28: 0 | BE28: 0001887881_16ARAS1002 | BF28: TOKO NAUFAL | BG28: 0 | BH28: 1 | BI28: 1 | BJ28: 0
H29: 0001887881_16AMKM1076 | I29: TOKO DINA AKBAR SATU | J29: 0 | K29: 1 | L29: 1 | M29: 0 | O29: 0001887881_16ASOD1052 | P29: TOKO HERY JAYA | Q29: 0 | R29: 1 | S29: 1 | T29: 0 | V29: 0001887881_16ANLW1097 | W29: TOKO RIZKY | X29: 1 | Y29: 0 | Z29: 0 | AA29: 1 | AC29: 0001887881_A9074039 | AD29: TOKO BAPAK YENI | AE29: 1 | AF29: 1 | AG29: 0 | AH29: 0 | AQ29: 0001887881_16AMKQ1080 | AR29: TOKO SUMBER RIZKI SNACK DUA | AS29: 0 | AT29: 1 | AU29: 1 | AV29: 1 | AX29: 0001887881_16ARBE1004 | AY29: TOKO AMANAH | AZ29: 0 | BA29: 1 | BB29: 1 | BC29: 1 | BE29: 0001887881_16ARAS1005 | BF29: TOKO TIGA SAUDARA 2 | BG29: 0 | BH29: 1 | BI29: 1 | BJ29: 0
H30: 0001887881_16AMKN1077 | I30: TOKO SUGIH MAKMUR | J30: 1 | K30: 1 | L30: 1 | M30: 1 | O30: 0001887881_16ASOH1002 | P30: TOKO SEKA BINA UNGGUL | Q30: 1 | R30: 0 | S30: 0 | T30: 1 | V30: 0001887881_16ANLW1101 | W30: TOKO ERDE | X30: 0 | Y30: 0 | Z30: 0 | AA30: 1 | AC30: Grand Total | AE30: 8 | AF30: 12 | AG30: 9 | AH30: 19 | AQ30: 0001887881_16AMKR1008 | AR30: TOKO FERI | AS30: 1 | AT30: 1 | AU30: 1 | AV30: 0 | AX30: 0001887881_16ARBF1003 | AY30: TOKO APRIL | AZ30: 0 | BA30: 0 | BB30: 0 | BC30: 1 | BE30: 0001887881_16ARAS1012 | BF30: TOKO ERI 1 | BG30: 0 | BH30: 1 | BI30: 1 | BJ30: 1
H31: 0001887881_16ANLV1001 | I31: Toko Ara | J31: 1 | K31: 1 | L31: 1 | M31: 1 | O31: 0001887881_16ASOH1013 | P31: ARKAAN | Q31: 0 | R31: 1 | S31: 1 | T31: 0 | V31: 0001887881_16ANLW1102 | W31: TOKO SAMA MAJU | X31: 0 | Y31: 0 | Z31: 0 | AA31: 1 | AQ31: 0001887881_16ANLW1004 | AR31: TOKO HELEN | AS31: 0 | AT31: 0 | AU31: 1 | AV31: 1 | AX31: 0001887881_16ARBO1012 | AY31: TOKO ADITYA PLASTIK | AZ31: 0 | BA31: 1 | BB31: 1 | BC31: 0 | BE31: 0001887881_16ARAS1015 | BF31: TOKO SIMPUR FROZEN | BG31: 0 | BH31: 0 | BI31: 0 | BJ31: 1
H32: 0001887881_16ANLW1062 | I32: TOKO BESH MART | J32: 0 | K32: 0 | L32: 0 | M32: 1 | O32: 0001887881_16ASOH1014 | P32: TOKO JAWA PLASTIK | Q32: 0 | R32: 1 | S32: 1 | T32: 0 | V32: 0001887881_16ANLW1105 | W32: TOKO BILAL DUA | X32: 0 | Y32: 1 | Z32: 0 | AA32: 1 | AQ32: 0001887881_16ANLX1011 | AR32: TOKO CERIA | AS32: 0 | AT32: 0 | AU32: 1 | AV32: 1 | AX32: 0001887881_16ARBO1017 | AY32: Toko SUMBER REZEKI | AZ32: 1 | BA32: 0 | BB32: 0 | BC32: 1 | BE32: 0001887881_16ARAS1016 | BF32: TOKO ALFARIZI | BG32: 1 | BH32: 0 | BI32: 0 | BJ32: 1
H33: 0001887881_16ANNJ1011 | I33: TOKO MAJU BERSAMA SAUDARA MBS | J33: 0 | K33: 0 | L33: 1 | M33: 1 | O33: 0001887881_16ASOH1015 | P33: Toko Al barkah | Q33: 1 | R33: 1 | S33: 1 | T33: 0 | V33: 0001887881_16ANLX1002 | W33: TOKO OM IPEN | X33: 0 | Y33: 1 | Z33: 0 | AA33: 0 | AQ33: 0001887881_16ANNK1005 | AR33: TOKO BOY | AS33: 1 | AT33: 1 | AU33: 1 | AV33: 0 | AX33: 0001887881_16ARRJ1001 | AY33: Toko intan plastik | AZ33: 0 | BA33: 1 | BB33: 1 | BC33: 1 | BE33: 0001887881_16ARAS1020 | BF33: TOKO ROYAL | BG33: 0 | BH33: 0 | BI33: 0 | BJ33: 1
H34: 0001887881_16ANNL1005 | I34: TOKO SEJAHTERA | J34: 0 | K34: 1 | L34: 1 | M34: 0 | O34: 0001887881_16ASOH1100 | P34: TOKO RISQY KAKA | Q34: 1 | R34: 0 | S34: 0 | T34: 1 | V34: 0001887881_16ANLY1004 | W34: Toko Puput | X34: 1 | Y34: 0 | Z34: 1 | AA34: 1 | AQ34: 0001887881_16APFP1035 | AR34: TOKO GALUH DUA | AS34: 1 | AT34: 1 | AU34: 1 | AV34: 0 | AX34: 0001887881_16ARRJ1002 | AY34: TOKO TARGIS | AZ34: 1 | BA34: 1 | BB34: 1 | BC34: 1 | BE34: 0001887881_16ARAS1021 | BF34: TOKO HASIBUAN | BG34: 1 | BH34: 0 | BI34: 0 | BJ34: 1
H35: 0001887881_16ANNL1035 | I35: TOKO RINGGANA | J35: 0 | K35: 0 | L35: 0 | M35: 1 | O35: 0001887881_16ASOH1104 | P35: TOKO BERSAUDARA | Q35: 1 | R35: 1 | S35: 0 | T35: 0 | V35: 0001887881_16ANLY1006 | W35: TOKO OWAK | X35: 0 | Y35: 1 | Z35: 1 | AA35: 0 | AQ35: 0001887881_16APFP1060 | AR35: TOKO PUTRO PAWIRO | AS35: 0 | AT35: 1 | AU35: 0 | AV35: 0 | AX35: 0001887881_16ARRJ1003 | AY35: TOKO TASYA MUKTIWARI | AZ35: 0 | BA35: 0 | BB35: 0 | BC35: 1 | BE35: 0001887881_16ARAS1028 | BF35: TOKO CEU ELA | BG35: 0 | BH35: 0 | BI35: 1 | BJ35: 1
H36: 0001887881_16APFN1035 | I36: Toko Barokah | J36: 0 | K36: 1 | L36: 1 | M36: 1 | O36: 0001887881_16ASTF1014 | P36: Toko Bela | Q36: 1 | R36: 1 | S36: 1 | T36: 1 | V36: 0001887881_16APFO1041 | W36: TOKO AJAT | X36: 1 | Y36: 1 | Z36: 1 | AA36: 0 | AQ36: 0001887881_16APFP1066 | AR36: Toko Sumber rizki snack empat | AS36: 1 | AT36: 1 | AU36: 1 | AV36: 0 | AX36: 0001887881_16ARRJ1004 | AY36: Toko Nurul | AZ36: 1 | BA36: 0 | BB36: 0 | BC36: 0 | BE36: 0001887881_16ARAS1029 | BF36: TOKO HASANAH | BG36: 0 | BH36: 1 | BI36: 0 | BJ36: 1
H37: 0001887881_16ARRG1001 | I37: TOKO IBU SITI | J37: 0 | K37: 1 | L37: 0 | M37: 1 | O37: 0001887881_16ASTF1018 | P37: TOKO ANGEL | Q37: 0 | R37: 1 | S37: 0 | T37: 0 | V37: 0001887881_16APFO1042 | W37: TOKO INDAH | X37: 1 | Y37: 1 | Z37: 1 | AA37: 1 | AQ37: 0001887881_16APFQ1010 | AR37: TOKO SANDY | AS37: 0 | AT37: 1 | AU37: 1 | AV37: 1 | AX37: 0001887881_16ARRL1002 | AY37: TOKO YONO | AZ37: 0 | BA37: 1 | BB37: 0 | BC37: 0 | BE37: 0001887881_16ARAT1004 | BF37: TOKO VERONICA | BG37: 1 | BH37: 0 | BI37: 0 | BJ37: 1
H38: 0001887881_16ASNQ1022 | I38: TOKO ARSI | J38: 0 | K38: 1 | L38: 0 | M38: 0 | O38: 0001887881_20093 | P38: Toko IBRAHIM | Q38: 0 | R38: 0 | S38: 0 | T38: 1 | V38: 0001887881_16APFO1043 | W38: TOKO ADAM FROZEN | X38: 0 | Y38: 0 | Z38: 1 | AA38: 1 | AQ38: 0001887881_16APFQ1012 | AR38: TOKO YOLANDA PELASTIK | AS38: 0 | AT38: 1 | AU38: 1 | AV38: 0 | AX38: 0001887881_16ARRL1006 | AY38: TOKO PASAR MINI | AZ38: 0 | BA38: 1 | BB38: 0 | BC38: 0 | BE38: 0001887881_16ARAU1001 | BF38: TOKO HAJI ITANG | BG38: 0 | BH38: 0 | BI38: 0 | BJ38: 0
H39: 0001887881_16ASNQ1027 | I39: TOKO ANUGERAH PERMATA | J39: 0 | K39: 1 | L39: 1 | M39: 0 | O39: 0001887881_20357 | P39: TOKO BENUA BARU | Q39: 1 | R39: 1 | S39: 0 | T39: 1 | V39: 0001887881_16ASNP1024 | W39: TOKO HIKMAH PLASTIK DUA | X39: 0 | Y39: 1 | Z39: 1 | AA39: 0 | AQ39: 0001887881_16APFQ1013 | AR39: TOKO HASIBUAN | AS39: 0 | AT39: 1 | AU39: 0 | AV39: 1 | AX39: 0001887881_16ARRL1007 | AY39: Toko Barokah | AZ39: 0 | BA39: 0 | BB39: 0 | BC39: 1 | BE39: 0001887881_16ARAV1004 | BF39: TOKO BAROKAH 2 | BG39: 1 | BH39: 1 | BI39: 1 | BJ39: 1
H40: 0001887881_16ASNQ1030 | I40: TOKO ALAN | J40: 1 | K40: 0 | L40: 1 | M40: 1 | O40: 0001887881_20716 | P40: TOKO AMANAH JAYA | Q40: 0 | R40: 1 | S40: 1 | T40: 0 | V40: 0001887881_16ASNQ1015 | W40: TOKO RESTU JAYA | X40: 1 | Y40: 0 | Z40: 0 | AA40: 1 | AQ40: 0001887881_16APFQ1015 | AR40: TOKO KEMBAR | AS40: 1 | AT40: 1 | AU40: 0 | AV40: 1 | AX40: 0001887881_16ARRL1010 | AY40: TOKO BANYU URIP | AZ40: 0 | BA40: 0 | BB40: 0 | BC40: 1 | BE40: 0001887881_16ARAV1005 | BF40: TOKO SEMBAKO HIRA | BG40: 1 | BH40: 1 | BI40: 1 | BJ40: 0
...

Sheet RAW SO
A1: Calendar[Month] | B1: Oct
A2: Channel[Channel L2 name] | B2: Provision | R2: =R4/R3 -> 0.14127219 | S2: =S4/S3 -> 0.13757396 | T2: =T4/T3 -> 0.14940828 | U2: =U4/U3 -> 0.15902367
R3: 1352 | S3: 1352 | T3: 1352 | U3: 1352
A4: Sum of [Sellout2] | C4: SKU[Local prod hier L5] | N4: 1.056 | O4: 1.056 | P4: 1.056 | Q4: 1.056 | R4: =SUBTOTAL(9,R6:R1048576) -> 191 | S4: =SUBTOTAL(9,S6:S1048576) -> 186 | T4: =SUBTOTAL(9,T6:T1048576) -> 202 | U4: =SUBTOTAL(9,U6:U1048576) -> 215
A5: Outlet[Outlet code] | B5: Outlet[Outlet name] | C5: Bear Brand STM 189ml SP | D5: Dancow Instant Sich | E5: Milo Tonic Sich | F5: Milo UHT | H5: Outlet[Outlet code] | I5: Outlet[Outlet name] | J5: Bear Brand STM 189ml SP | K5: Dancow Instant Sich | L5: Milo Tonic Sich | M5: Milo UHT | N5: Bear Brand STM 189ml SP GROSS | O5: Dancow Instant Sich GROSS | P5: Milo Tonic Sich GROSS | Q5: Milo UHT GROSS | R5: MSS BB | S5: MSS Dc Inst | T5: MSS Milo Ton | U5: MSS Milo UHT | V5: Salesman Name | W5: Visit Day
A6: 0001887881_10056 | B6: TOKO PRIMA JAYA 6 | C6: 25086.174 | D6: 123372.63 | H6: =A6 -> 0001887881_10056 | I6: =B6 -> TOKO PRIMA JAYA 6 | J6: =C6 -> 25086.174 | K6: =D6 -> 123372.63 | L6: =E6 -> 0 | M6: =F6 -> 0 | N6: =J6*$N$4 -> 26491 | O6: =K6*$O$4 -> 130281.5 | P6: =L6*$P$4 -> 0 | Q6: =M6*$Q$4 -> 0 | R6: =IF(N6>Treshold!$D$4,1,0) -> 1 | S6: =IF(O6>Treshold!$D$5,1,0) -> 1 | T6: =IF(P6>Treshold!$D$6,1,0) -> 0 | U6: =IF(Q6>Treshold!$D$7,1,0) -> 0 | V6: =IFERROR(VLOOKUP(H6,jp!AL:AP,4,0),"Belum Masuk JP") -> Tuan Suhanda | W6: =IFERROR(VLOOKUP(H6,jp!AL:AP,5,0),0) -> 3
A7: 0001887881_10070 | B7: ARIA | D7: 246745.27 | E7: 635583.33 | H7: =A7 -> 0001887881_10070 | I7: =B7 -> ARIA | J7: =C7 -> 0 | K7: =D7 -> 246745.27 | L7: =E7 -> 635583.33 | M7: =F7 -> 0 | N7: =J7*$N$4 -> 0 | O7: =K7*$O$4 -> 260563 | P7: =L7*$P$4 -> 671176 | Q7: =M7*$Q$4 -> 0 | R7: =IF(N7>Treshold!$D$4,1,0) -> 0 | S7: =IF(O7>Treshold!$D$5,1,0) -> 1 | T7: =IF(P7>Treshold!$D$6,1,0) -> 1 | U7: =IF(Q7>Treshold!$D$7,1,0) -> 0 | V7: =IFERROR(VLOOKUP(H7,jp!AL:AP,4,0),"Belum Masuk JP") -> Tuan Suhanda | W7: =IFERROR(VLOOKUP(H7,jp!AL:AP,5,0),0) -> 1
A8: 0001887881_10083 | B8: TOKO NURUL ALFI | C8: 501723.48 | F8: 100677.01 | H8: =A8 -> 0001887881_10083 | I8: =B8 -> TOKO NURUL ALFI | J8: =C8 -> 501723.48 | K8: =D8 -> 0 | L8: =E8 -> 0 | M8: =F8 -> 100677.01 | N8: =J8*$N$4 -> 529820 | O8: =K8*$O$4 -> 0 | P8: =L8*$P$4 -> 0 | Q8: =M8*$Q$4 -> 106314.92 | R8: =IF(N8>Treshold!$D$4,1,0) -> 1 | S8: =IF(O8>Treshold!$D$5,1,0) -> 0 | T8: =IF(P8>Treshold!$D$6,1,0) -> 0 | U8: =IF(Q8>Treshold!$D$7,1,0) -> 1 | V8: =IFERROR(VLOOKUP(H8,jp!AL:AP,4,0),"Belum Masuk JP") -> Abdul | W8: =IFERROR(VLOOKUP(H8,jp!AL:AP,5,0),0) -> 3
A9: 0001887881_10131 | B9: TOKO Mulia | C9: 1003447 | D9: 61686.316 | H9: =A9 -> 0001887881_10131 | I9: =B9 -> TOKO Mulia | J9: =C9 -> 1003447 | K9: =D9 -> 61686.316 | L9: =E9 -> 0 | M9: =F9 -> 0 | N9: =J9*$N$4 -> 1059640 | O9: =K9*$O$4 -> 65140.75 | P9: =L9*$P$4 -> 0 | Q9: =M9*$Q$4 -> 0 | R9: =IF(N9>Treshold!$D$4,1,0) -> 1 | S9: =IF(O9>Treshold!$D$5,1,0) -> 1 | T9: =IF(P9>Treshold!$D$6,1,0) -> 0 | U9: =IF(Q9>Treshold!$D$7,1,0) -> 0 | V9: =IFERROR(VLOOKUP(H9,jp!AL:AP,4,0),"Belum Masuk JP") -> Tuan Suhanda | W9: =IFERROR(VLOOKUP(H9,jp!AL:AP,5,0),0) -> 2
A10: 0001887881_10200 | B10: Toko Berkah | C10: 250861.74 | E10: 635583.33 | F10: 150635.42 | H10: =A10 -> 0001887881_10200 | I10: =B10 -> Toko Berkah | J10: =C10 -> 250861.74 | K10: =D10 -> 0 | L10: =E10 -> 635583.33 | M10: =F10 -> 150635.42 | N10: =J10*$N$4 -> 264910 | O10: =K10*$O$4 -> 0 | P10: =L10*$P$4 -> 671176 | Q10: =M10*$Q$4 -> 159071 | R10: =IF(N10>Treshold!$D$4,1,0) -> 1 | S10: =IF(O10>Treshold!$D$5,1,0) -> 0 | T10: =IF(P10>Treshold!$D$6,1,0) -> 1 | U10: =IF(Q10>Treshold!$D$7,1,0) -> 1 | V10: =IFERROR(VLOOKUP(H10,jp!AL:AP,4,0),"Belum Masuk JP") -> Abdul | W10: =IFERROR(VLOOKUP(H10,jp!AL:AP,5,0),0) -> 2
A11: 0001887881_10213 | B11: TOKO DAFFA | C11: 3762926.1 | D11: 986981.06 | E11: 3177916.7 | F11: 745392.99 | H11: =A11 -> 0001887881_10213 | I11: =B11 -> TOKO DAFFA | J11: =C11 -> 3762926.1 | K11: =D11 -> 986981.06 | L11: =E11 -> 3177916.7 | M11: =F11 -> 745392.99 | N11: =J11*$N$4 -> 3973650 | O11: =K11*$O$4 -> 1042252 | P11: =L11*$P$4 -> 3355880 | Q11: =M11*$Q$4 -> 787135 | R11: =IF(N11>Treshold!$D$4,1,0) -> 1 | S11: =IF(O11>Treshold!$D$5,1,0) -> 1 | T11: =IF(P11>Treshold!$D$6,1,0) -> 1 | U11: =IF(Q11>Treshold!$D$7,1,0) -> 1 | V11: =IFERROR(VLOOKUP(H11,jp!AL:AP,4,0),"Belum Masuk JP") -> Fariq | W11: =IFERROR(VLOOKUP(H11,jp!AL:AP,5,0),0) -> 5
A12: 0001887881_10217 | B12: TOKO AULIA EMPAT | F12: 150635.42 | H12: =A12 -> 0001887881_10217 | I12: =B12 -> TOKO AULIA EMPAT | J12: =C12 -> 0 | K12: =D12 -> 0 | L12: =E12 -> 0 | M12: =F12 -> 150635.42 | N12: =J12*$N$4 -> 0 | O12: =K12*$O$4 -> 0 | P12: =L12*$P$4 -> 0 | Q12: =M12*$Q$4 -> 159071 | R12: =IF(N12>Treshold!$D$4,1,0) -> 0 | S12: =IF(O12>Treshold!$D$5,1,0) -> 0 | T12: =IF(P12>Treshold!$D$6,1,0) -> 0 | U12: =IF(Q12>Treshold!$D$7,1,0) -> 1 | V12: =IFERROR(VLOOKUP(H12,jp!AL:AP,4,0),"Belum Masuk JP") -> Watinah Amalia | W12: =IFERROR(VLOOKUP(H12,jp!AL:AP,5,0),0) -> 4
A13: 0001887881_10242 | B13: Toko Baru VIII | C13: 250861.74 | E13: 333681.25 | F13: 9897.197 | H13: =A13 -> 0001887881_10242 | I13: =B13 -> Toko Baru VIII | J13: =C13 -> 250861.74 | K13: =D13 -> 0 | L13: =E13 -> 333681.25 | M13: =F13 -> 9897.197 | N13: =J13*$N$4 -> 264910 | O13: =K13*$O$4 -> 0 | P13: =L13*$P$4 -> 352367.4 | Q13: =M13*$Q$4 -> 10451.44 | R13: =IF(N13>Treshold!$D$4,1,0) -> 1 | S13: =IF(O13>Treshold!$D$5,1,0) -> 0 | T13: =IF(P13>Treshold!$D$6,1,0) -> 1 | U13: =IF(Q13>Treshold!$D$7,1,0) -> 0 | V13: =IFERROR(VLOOKUP(H13,jp!AL:AP,4,0),"Belum Masuk JP") -> Abdul | W13: =IFERROR(VLOOKUP(H13,jp!AL:AP,5,0),0) -> 4
A14: 0001887881_10311 | B14: Terang Jaya | E14: 3177916.7 | F14: 1579860.8 | H14: =A14 -> 0001887881_10311 | I14: =B14 -> Terang Jaya | J14: =C14 -> 0 | K14: =D14 -> 0 | L14: =E14 -> 3177916.7 | M14: =F14 -> 1579860.8 | N14: =J14*$N$4 -> 0 | O14: =K14*$O$4 -> 0 | P14: =L14*$P$4 -> 3355880 | Q14: =M14*$Q$4 -> 1668333 | R14: =IF(N14>Treshold!$D$4,1,0) -> 0 | S14: =IF(O14>Treshold!$D$5,1,0) -> 0 | T14: =IF(P14>Treshold!$D$6,1,0) -> 1 | U14: =IF(Q14>Treshold!$D$7,1,0) -> 1 | V14: =IFERROR(VLOOKUP(H14,jp!AL:AP,4,0),"Belum Masuk JP") -> Tuan Suhanda | W14: =IFERROR(VLOOKUP(H14,jp!AL:AP,5,0),0) -> 2
A15: 0001887881_10327 | B15: TOKO PARMAN | D15: 61686.316 | F15: 3998660 | H15: =A15 -> 0001887881_10327 | I15: =B15 -> TOKO PARMAN | J15: =C15 -> 0 | K15: =D15 -> 61686.316 | L15: =E15 -> 0 | M15: =F15 -> 3998660 | N15: =J15*$N$4 -> 0 | O15: =K15*$O$4 -> 65140.75 | P15: =L15*$P$4 -> 0 | Q15: =M15*$Q$4 -> 4222585 | R15: =IF(N15>Treshold!$D$4,1,0) -> 0 | S15: =IF(O15>Treshold!$D$5,1,0) -> 1 | T15: =IF(P15>Treshold!$D$6,1,0) -> 0 | U15: =IF(Q15>Treshold!$D$7,1,0) -> 1 | V15: =IFERROR(VLOOKUP(H15,jp!AL:AP,4,0),"Belum Masuk JP") -> Tuan Suhanda | W15: =IFERROR(VLOOKUP(H15,jp!AL:AP,5,0),0) -> 2
A16: 0001887881_10392 | B16: TOKO ALJABAL | C16: 752585.23 | F16: 746949.81 | H16: =A16 -> 0001887881_10392 | I16: =B16 -> TOKO ALJABAL | J16: =C16 -> 752585.23 | K16: =D16 -> 0 | L16: =E16 -> 0 | M16: =F16 -> 746949.81 | N16: =J16*$N$4 -> 794730 | O16: =K16*$O$4 -> 0 | P16: =L16*$P$4 -> 0 | Q16: =M16*$Q$4 -> 788779 | R16: =IF(N16>Treshold!$D$4,1,0) -> 1 | S16: =IF(O16>Treshold!$D$5,1,0) -> 0 | T16: =IF(P16>Treshold!$D$6,1,0) -> 0 | U16: =IF(Q16>Treshold!$D$7,1,0) -> 1 | V16: =IFERROR(VLOOKUP(H16,jp!AL:AP,4,0),"Belum Masuk JP") -> Tuan Suhanda | W16: =IFERROR(VLOOKUP(H16,jp!AL:AP,5,0),0) -> 5
A17: 0001887881_1523358 | B17: TOKO HAJI DIANA | C17: 2508617.4 | D17: 986981.06 | E17: 953375 | F17: 89074.811 | H17: =A17 -> 0001887881_1523358 | I17: =B17 -> TOKO HAJI DIANA | J17: =C17 -> 2508617.4 | K17: =D17 -> 986981.06 | L17: =E17 -> 953375 | M17: =F17 -> 89074.811 | N17: =J17*$N$4 -> 2649100 | O17: =K17*$O$4 -> 1042252 | P17: =L17*$P$4 -> 1006764 | Q17: =M17*$Q$4 -> 94063 | R17: =IF(N17>Treshold!$D$4,1,0) -> 1 | S17: =IF(O17>Treshold!$D$5,1,0) -> 1 | T17: =IF(P17>Treshold!$D$6,1,0) -> 1 | U17: =IF(Q17>Treshold!$D$7,1,0) -> 1 | V17: =IFERROR(VLOOKUP(H17,jp!AL:AP,4,0),"Belum Masuk JP") -> Watinah Amalia | W17: =IFERROR(VLOOKUP(H17,jp!AL:AP,5,0),0) -> 2
A18: 0001887881_1523377 | B18: TOKO AL AZHAR | C18: 25086.174 | D18: 61686.316 | E18: 1588958.3 | F18: 746644.89 | H18: =A18 -> 0001887881_1523377 | I18: =B18 -> TOKO AL AZHAR | J18: =C18 -> 25086.174 | K18: =D18 -> 61686.316 | L18: =E18 -> 1588958.3 | M18: =F18 -> 746644.89 | N18: =J18*$N$4 -> 26491 | O18: =K18*$O$4 -> 65140.75 | P18: =L18*$P$4 -> 1677940 | Q18: =M18*$Q$4 -> 788457 | R18: =IF(N18>Treshold!$D$4,1,0) -> 1 | S18: =IF(O18>Treshold!$D$5,1,0) -> 1 | T18: =IF(P18>Treshold!$D$6,1,0) -> 1 | U18: =IF(Q18>Treshold!$D$7,1,0) -> 1 | V18: =IFERROR(VLOOKUP(H18,jp!AL:AP,4,0),"Belum Masuk JP") -> Watinah Amalia | W18: =IFERROR(VLOOKUP(H18,jp!AL:AP,5,0),0) -> 1
A19: 0001887881_1523378 | B19: TOKO KORBI STORE | F19: 89074.811 | H19: =A19 -> 0001887881_1523378 | I19: =B19 -> TOKO KORBI STORE | J19: =C19 -> 0 | K19: =D19 -> 0 | L19: =E19 -> 0 | M19: =F19 -> 89074.811 | N19: =J19*$N$4 -> 0 | O19: =K19*$O$4 -> 0 | P19: =L19*$P$4 -> 0 | Q19: =M19*$Q$4 -> 94063 | R19: =IF(N19>Treshold!$D$4,1,0) -> 0 | S19: =IF(O19>Treshold!$D$5,1,0) -> 0 | T19: =IF(P19>Treshold!$D$6,1,0) -> 0 | U19: =IF(Q19>Treshold!$D$7,1,0) -> 1 | V19: =IFERROR(VLOOKUP(H19,jp!AL:AP,4,0),"Belum Masuk JP") -> Watinah Amalia | W19: =IFERROR(VLOOKUP(H19,jp!AL:AP,5,0),0) -> 4
A20: 0001887881_161012 | B20: Toko Dini (psMGT) | D20: 61686.316 | H20: =A20 -> 0001887881_161012 | I20: =B20 -> Toko Dini (psMGT) | J20: =C20 -> 0 | K20: =D20 -> 61686.316 | L20: =E20 -> 0 | M20: =F20 -> 0 | N20: =J20*$N$4 -> 0 | O20: =K20*$O$4 -> 65140.75 | P20: =L20*$P$4 -> 0 | Q20: =M20*$Q$4 -> 0 | R20: =IF(N20>Treshold!$D$4,1,0) -> 0 | S20: =IF(O20>Treshold!$D$5,1,0) -> 1 | T20: =IF(P20>Treshold!$D$6,1,0) -> 0 | U20: =IF(Q20>Treshold!$D$7,1,0) -> 0 | V20: =IFERROR(VLOOKUP(H20,jp!AL:AP,4,0),"Belum Masuk JP") -> Tuan Suhanda | W20: =IFERROR(VLOOKUP(H20,jp!AL:AP,5,0),0) -> 5
A21: 0001887881_16AKRT1003 | B21: TOKO FB MULYA SEJAHTERA | E21: 1588958.3 | F21: 1198551.1 | H21: =A21 -> 0001887881_16AKRT1003 | I21: =B21 -> TOKO FB MULYA SEJAHTERA | J21: =C21 -> 0 | K21: =D21 -> 0 | L21: =E21 -> 1588958.3 | M21: =F21 -> 1198551.1 | N21: =J21*$N$4 -> 0 | O21: =K21*$O$4 -> 0 | P21: =L21*$P$4 -> 1677940 | Q21: =M21*$Q$4 -> 1265670 | R21: =IF(N21>Treshold!$D$4,1,0) -> 0 | S21: =IF(O21>Treshold!$D$5,1,0) -> 0 | T21: =IF(P21>Treshold!$D$6,1,0) -> 1 | U21: =IF(Q21>Treshold!$D$7,1,0) -> 1 | V21: =IFERROR(VLOOKUP(H21,jp!AL:AP,4,0),"Belum Masuk JP") -> Watinah Amalia | W21: =IFERROR(VLOOKUP(H21,jp!AL:AP,5,0),0) -> 6
A22: 0001887881_16AKRT1007 | B22: TOKO APOTIK AYAH | C22: 250861.74 | F22: 239710.23 | H22: =A22 -> 0001887881_16AKRT1007 | I22: =B22 -> TOKO APOTIK AYAH | J22: =C22 -> 250861.74 | K22: =D22 -> 0 | L22: =E22 -> 0 | M22: =F22 -> 239710.23 | N22: =J22*$N$4 -> 264910 | O22: =K22*$O$4 -> 0 | P22: =L22*$P$4 -> 0 | Q22: =M22*$Q$4 -> 253134 | R22: =IF(N22>Treshold!$D$4,1,0) -> 1 | S22: =IF(O22>Treshold!$D$5,1,0) -> 0 | T22: =IF(P22>Treshold!$D$6,1,0) -> 0 | U22: =IF(Q22>Treshold!$D$7,1,0) -> 1 | V22: =IFERROR(VLOOKUP(H22,jp!AL:AP,4,0),"Belum Masuk JP") -> Watinah Amalia | W22: =IFERROR(VLOOKUP(H22,jp!AL:AP,5,0),0) -> 6
A23: 0001887881_16AKRT1010 | B23: TOKO ELSA TARUMAJAYA | C23: 501723.48 | E23: 31779.167 | F23: 89074.811 | H23: =A23 -> 0001887881_16AKRT1010 | I23: =B23 -> TOKO ELSA TARUMAJAYA | J23: =C23 -> 501723.48 | K23: =D23 -> 0 | L23: =E23 -> 31779.167 | M23: =F23 -> 89074.811 | N23: =J23*$N$4 -> 529820 | O23: =K23*$O$4 -> 0 | P23: =L23*$P$4 -> 33558.8 | Q23: =M23*$Q$4 -> 94063 | R23: =IF(N23>Treshold!$D$4,1,0) -> 1 | S23: =IF(O23>Treshold!$D$5,1,0) -> 0 | T23: =IF(P23>Treshold!$D$6,1,0) -> 1 | U23: =IF(Q23>Treshold!$D$7,1,0) -> 1 | V23: =IFERROR(VLOOKUP(H23,jp!AL:AP,4,0),"Belum Masuk JP") -> Watinah Amalia | W23: =IFERROR(VLOOKUP(H23,jp!AL:AP,5,0),0) -> 6
A24: 0001887881_16AKRX1004 | B24: TOKO KEKE FROZEN | E24: 79447.917 | F24: 149770.51 | H24: =A24 -> 0001887881_16AKRX1004 | I24: =B24 -> TOKO KEKE FROZEN | J24: =C24 -> 0 | K24: =D24 -> 0 | L24: =E24 -> 79447.917 | M24: =F24 -> 149770.51 | N24: =J24*$N$4 -> 0 | O24: =K24*$O$4 -> 0 | P24: =L24*$P$4 -> 83897 | Q24: =M24*$Q$4 -> 158157.66 | R24: =IF(N24>Treshold!$D$4,1,0) -> 0 | S24: =IF(O24>Treshold!$D$5,1,0) -> 0 | T24: =IF(P24>Treshold!$D$6,1,0) -> 1 | U24: =IF(Q24>Treshold!$D$7,1,0) -> 1 | V24: =IFERROR(VLOOKUP(H24,jp!AL:AP,4,0),"Belum Masuk JP") -> Watinah Amalia | W24: =IFERROR(VLOOKUP(H24,jp!AL:AP,5,0),0) -> 6
A25: 0001887881_16AKRZ1004 | B25: ALMIRA JAYA MANDIRI | E25: 79447.917 | F25: 138032.61 | H25: =A25 -> 0001887881_16AKRZ1004 | I25: =B25 -> ALMIRA JAYA MANDIRI | J25: =C25 -> 0 | K25: =D25 -> 0 | L25: =E25 -> 79447.917 | M25: =F25 -> 138032.61 | N25: =J25*$N$4 -> 0 | O25: =K25*$O$4 -> 0 | P25: =L25*$P$4 -> 83897 | Q25: =M25*$Q$4 -> 145762.44 | R25: =IF(N25>Treshold!$D$4,1,0) -> 0 | S25: =IF(O25>Treshold!$D$5,1,0) -> 0 | T25: =IF(P25>Treshold!$D$6,1,0) -> 1 | U25: =IF(Q25>Treshold!$D$7,1,0) -> 1 | V25: =IFERROR(VLOOKUP(H25,jp!AL:AP,4,0),"Belum Masuk JP") -> Watinah Amalia | W25: =IFERROR(VLOOKUP(H25,jp!AL:AP,5,0),0) -> 6
A26: 0001887881_16AKWU1003 | B26: Toko Makmur Sentosa | C26: 83620.578 | D26: 61686.316 | E26: 47668.75 | H26: =A26 -> 0001887881_16AKWU1003 | I26: =B26 -> Toko Makmur Sentosa | J26: =C26 -> 83620.578 | K26: =D26 -> 61686.316 | L26: =E26 -> 47668.75 | M26: =F26 -> 0 | N26: =J26*$N$4 -> 88303.33 | O26: =K26*$O$4 -> 65140.75 | P26: =L26*$P$4 -> 50338.2 | Q26: =M26*$Q$4 -> 0 | R26: =IF(N26>Treshold!$D$4,1,0) -> 1 | S26: =IF(O26>Treshold!$D$5,1,0) -> 1 | T26: =IF(P26>Treshold!$D$6,1,0) -> 1 | U26: =IF(Q26>Treshold!$D$7,1,0) -> 0 | V26: =IFERROR(VLOOKUP(H26,jp!AL:AP,4,0),"Belum Masuk JP") -> Watinah Amalia | W26: =IFERROR(VLOOKUP(H26,jp!AL:AP,5,0),0) -> 5
A27: 0001887881_16AKWV1003 | B27: Toko Simas | C27: 501723.48 | D27: 493490.53 | E27: 317791.67 | F27: 417859.85 | H27: =A27 -> 0001887881_16AKWV1003 | I27: =B27 -> Toko Simas | J27: =C27 -> 501723.48 | K27: =D27 -> 493490.53 | L27: =E27 -> 317791.67 | M27: =F27 -> 417859.85 | N27: =J27*$N$4 -> 529820 | O27: =K27*$O$4 -> 521126 | P27: =L27*$P$4 -> 335588 | Q27: =M27*$Q$4 -> 441260 | R27: =IF(N27>Treshold!$D$4,1,0) -> 1 | S27: =IF(O27>Treshold!$D$5,1,0) -> 1 | T27: =IF(P27>Treshold!$D$6,1,0) -> 1 | U27: =IF(Q27>Treshold!$D$7,1,0) -> 1 | V27: =IFERROR(VLOOKUP(H27,jp!AL:AP,4,0),"Belum Masuk JP") -> Watinah Amalia | W27: =IFERROR(VLOOKUP(H27,jp!AL:AP,5,0),0) -> 2
A28: 0001887881_16AKWV1005 | B28: TOKO MENARA DUA GROSIR | D28: 185058.95 | E28: 158895.83 | H28: =A28 -> 0001887881_16AKWV1005 | I28: =B28 -> TOKO MENARA DUA GROSIR | J28: =C28 -> 0 | K28: =D28 -> 185058.95 | L28: =E28 -> 158895.83 | M28: =F28 -> 0 | N28: =J28*$N$4 -> 0 | O28: =K28*$O$4 -> 195422.25 | P28: =L28*$P$4 -> 167794 | Q28: =M28*$Q$4 -> 0 | R28: =IF(N28>Treshold!$D$4,1,0) -> 0 | S28: =IF(O28>Treshold!$D$5,1,0) -> 1 | T28: =IF(P28>Treshold!$D$6,1,0) -> 1 | U28: =IF(Q28>Treshold!$D$7,1,0) -> 0 | V28: =IFERROR(VLOOKUP(H28,jp!AL:AP,4,0),"Belum Masuk JP") -> Watinah Amalia | W28: =IFERROR(VLOOKUP(H28,jp!AL:AP,5,0),0) -> 2
A29: 0001887881_16AKWV1008 | B29: TOKO LARIS TIGA | D29: 246745.27 | F29: 88124.053 | H29: =A29 -> 0001887881_16AKWV1008 | I29: =B29 -> TOKO LARIS TIGA | J29: =C29 -> 0 | K29: =D29 -> 246745.27 | L29: =E29 -> 0 | M29: =F29 -> 88124.053 | N29: =J29*$N$4 -> 0 | O29: =K29*$O$4 -> 260563 | P29: =L29*$P$4 -> 0 | Q29: =M29*$Q$4 -> 93059 | R29: =IF(N29>Treshold!$D$4,1,0) -> 0 | S29: =IF(O29>Treshold!$D$5,1,0) -> 1 | T29: =IF(P29>Treshold!$D$6,1,0) -> 0 | U29: =IF(Q29>Treshold!$D$7,1,0) -> 1 | V29: =IFERROR(VLOOKUP(H29,jp!AL:AP,4,0),"Belum Masuk JP") -> Fariq | W29: =IFERROR(VLOOKUP(H29,jp!AL:AP,5,0),0) -> 1
A30: 0001887881_16AKWV1009 | B30: toko eno | C30: 2508617.4 | D30: 1480471.6 | E30: 953375 | F30: 239710.23 | H30: =A30 -> 0001887881_16AKWV1009 | I30: =B30 -> toko eno | J30: =C30 -> 2508617.4 | K30: =D30 -> 1480471.6 | L30: =E30 -> 953375 | M30: =F30 -> 239710.23 | N30: =J30*$N$4 -> 2649100 | O30: =K30*$O$4 -> 1563378 | P30: =L30*$P$4 -> 1006764 | Q30: =M30*$Q$4 -> 253134 | R30: =IF(N30>Treshold!$D$4,1,0) -> 1 | S30: =IF(O30>Treshold!$D$5,1,0) -> 1 | T30: =IF(P30>Treshold!$D$6,1,0) -> 1 | U30: =IF(Q30>Treshold!$D$7,1,0) -> 1 | V30: =IFERROR(VLOOKUP(H30,jp!AL:AP,4,0),"Belum Masuk JP") -> Abdul | W30: =IFERROR(VLOOKUP(H30,jp!AL:AP,5,0),0) -> 2
A31: 0001887881_16AKWV1045 | B31: Toko Berkah | D31: 92529.479 | E31: 317791.67 | H31: =A31 -> 0001887881_16AKWV1045 | I31: =B31 -> Toko Berkah | J31: =C31 -> 0 | K31: =D31 -> 92529.479 | L31: =E31 -> 317791.67 | M31: =F31 -> 0 | N31: =J31*$N$4 -> 0 | O31: =K31*$O$4 -> 97711.13 | P31: =L31*$P$4 -> 335588 | Q31: =M31*$Q$4 -> 0 | R31: =IF(N31>Treshold!$D$4,1,0) -> 0 | S31: =IF(O31>Treshold!$D$5,1,0) -> 1 | T31: =IF(P31>Treshold!$D$6,1,0) -> 1 | U31: =IF(Q31>Treshold!$D$7,1,0) -> 0 | V31: =IFERROR(VLOOKUP(H31,jp!AL:AP,4,0),"Belum Masuk JP") -> Fariq | W31: =IFERROR(VLOOKUP(H31,jp!AL:AP,5,0),0) -> 3
A32: 0001887881_16AKWV1048 | B32: Toko Saidah | C32: 752585.23 | E32: 317791.67 | F32: 176248.11 | H32: =A32 -> 0001887881_16AKWV1048 | I32: =B32 -> Toko Saidah | J32: =C32 -> 752585.23 | K32: =D32 -> 0 | L32: =E32 -> 317791.67 | M32: =F32 -> 176248.11 | N32: =J32*$N$4 -> 794730 | O32: =K32*$O$4 -> 0 | P32: =L32*$P$4 -> 335588 | Q32: =M32*$Q$4 -> 186118 | R32: =IF(N32>Treshold!$D$4,1,0) -> 1 | S32: =IF(O32>Treshold!$D$5,1,0) -> 0 | T32: =IF(P32>Treshold!$D$6,1,0) -> 1 | U32: =IF(Q32>Treshold!$D$7,1,0) -> 1 | V32: =IFERROR(VLOOKUP(H32,jp!AL:AP,4,0),"Belum Masuk JP") -> Fariq | W32: =IFERROR(VLOOKUP(H32,jp!AL:AP,5,0),0) -> 6
A33: 0001887881_16AKWV1051 | B33: TOKO DODIT | C33: 250861.74 | F33: 101627.77 | H33: =A33 -> 0001887881_16AKWV1051 | I33: =B33 -> TOKO DODIT | J33: =C33 -> 250861.74 | K33: =D33 -> 0 | L33: =E33 -> 0 | M33: =F33 -> 101627.77 | N33: =J33*$N$4 -> 264910 | O33: =K33*$O$4 -> 0 | P33: =L33*$P$4 -> 0 | Q33: =M33*$Q$4 -> 107318.92 | R33: =IF(N33>Treshold!$D$4,1,0) -> 1 | S33: =IF(O33>Treshold!$D$5,1,0) -> 0 | T33: =IF(P33>Treshold!$D$6,1,0) -> 0 | U33: =IF(Q33>Treshold!$D$7,1,0) -> 1 | V33: =IFERROR(VLOOKUP(H33,jp!AL:AP,4,0),"Belum Masuk JP") -> Abdul | W33: =IFERROR(VLOOKUP(H33,jp!AL:AP,5,0),0) -> 2
A34: 0001887881_16AKWV1052 | B34: TOKO CERMAI | C34: 250861.74 | F34: 89074.811 | H34: =A34 -> 0001887881_16AKWV1052 | I34: =B34 -> TOKO CERMAI | J34: =C34 -> 250861.74 | K34: =D34 -> 0 | L34: =E34 -> 0 | M34: =F34 -> 89074.811 | N34: =J34*$N$4 -> 264910 | O34: =K34*$O$4 -> 0 | P34: =L34*$P$4 -> 0 | Q34: =M34*$Q$4 -> 94063 | R34: =IF(N34>Treshold!$D$4,1,0) -> 1 | S34: =IF(O34>Treshold!$D$5,1,0) -> 0 | T34: =IF(P34>Treshold!$D$6,1,0) -> 0 | U34: =IF(Q34>Treshold!$D$7,1,0) -> 1 | V34: =IFERROR(VLOOKUP(H34,jp!AL:AP,4,0),"Belum Masuk JP") -> Fariq | W34: =IFERROR(VLOOKUP(H34,jp!AL:AP,5,0),0) -> 5
A35: 0001887881_16AKWV3646 | B35: Toko Tamaguna | C35: 2508617.4 | F35: 1626633.5 | H35: =A35 -> 0001887881_16AKWV3646 | I35: =B35 -> Toko Tamaguna | J35: =C35 -> 2508617.4 | K35: =D35 -> 0 | L35: =E35 -> 0 | M35: =F35 -> 1626633.5 | N35: =J35*$N$4 -> 2649100 | O35: =K35*$O$4 -> 0 | P35: =L35*$P$4 -> 0 | Q35: =M35*$Q$4 -> 1717725 | R35: =IF(N35>Treshold!$D$4,1,0) -> 1 | S35: =IF(O35>Treshold!$D$5,1,0) -> 0 | T35: =IF(P35>Treshold!$D$6,1,0) -> 0 | U35: =IF(Q35>Treshold!$D$7,1,0) -> 1 | V35: =IFERROR(VLOOKUP(H35,jp!AL:AP,4,0),"Belum Masuk JP") -> Fariq | W35: =IFERROR(VLOOKUP(H35,jp!AL:AP,5,0),0) -> 3
A36: 0001887881_16AKWV3648 | B36: Toko Surya Mart | C36: 100344.7 | F36: 88124.053 | H36: =A36 -> 0001887881_16AKWV3648 | I36: =B36 -> Toko Surya Mart | J36: =C36 -> 100344.7 | K36: =D36 -> 0 | L36: =E36 -> 0 | M36: =F36 -> 88124.053 | N36: =J36*$N$4 -> 105964 | O36: =K36*$O$4 -> 0 | P36: =L36*$P$4 -> 0 | Q36: =M36*$Q$4 -> 93059 | R36: =IF(N36>Treshold!$D$4,1,0) -> 1 | S36: =IF(O36>Treshold!$D$5,1,0) -> 0 | T36: =IF(P36>Treshold!$D$6,1,0) -> 0 | U36: =IF(Q36>Treshold!$D$7,1,0) -> 1 | V36: =IFERROR(VLOOKUP(H36,jp!AL:AP,4,0),"Belum Masuk JP") -> Fariq | W36: =IFERROR(VLOOKUP(H36,jp!AL:AP,5,0),0) -> 6
A37: 0001887881_16AKWX1005 | B37: TOKO SEMBAKO AL BAROKAH EMPAT | D37: 493490.53 | E37: 317791.67 | H37: =A37 -> 0001887881_16AKWX1005 | I37: =B37 -> TOKO SEMBAKO AL BAROKAH EMPAT | J37: =C37 -> 0 | K37: =D37 -> 493490.53 | L37: =E37 -> 317791.67 | M37: =F37 -> 0 | N37: =J37*$N$4 -> 0 | O37: =K37*$O$4 -> 521126 | P37: =L37*$P$4 -> 335588 | Q37: =M37*$Q$4 -> 0 | R37: =IF(N37>Treshold!$D$4,1,0) -> 0 | S37: =IF(O37>Treshold!$D$5,1,0) -> 1 | T37: =IF(P37>Treshold!$D$6,1,0) -> 1 | U37: =IF(Q37>Treshold!$D$7,1,0) -> 0 | V37: =IFERROR(VLOOKUP(H37,jp!AL:AP,4,0),"Belum Masuk JP") -> Watinah Amalia | W37: =IFERROR(VLOOKUP(H37,jp!AL:AP,5,0),0) -> 1
A38: 0001887881_16AKWY1004 | B38: TOKO ROPIKOH | C38: 1254308.7 | D38: 493490.53 | E38: 1271166.7 | F38: 479420.45 | H38: =A38 -> 0001887881_16AKWY1004 | I38: =B38 -> TOKO ROPIKOH | J38: =C38 -> 1254308.7 | K38: =D38 -> 493490.53 | L38: =E38 -> 1271166.7 | M38: =F38 -> 479420.45 | N38: =J38*$N$4 -> 1324550 | O38: =K38*$O$4 -> 521126 | P38: =L38*$P$4 -> 1342352 | Q38: =M38*$Q$4 -> 506268 | R38: =IF(N38>Treshold!$D$4,1,0) -> 1 | S38: =IF(O38>Treshold!$D$5,1,0) -> 1 | T38: =IF(P38>Treshold!$D$6,1,0) -> 1 | U38: =IF(Q38>Treshold!$D$7,1,0) -> 1 | V38: =IFERROR(VLOOKUP(H38,jp!AL:AP,4,0),"Belum Masuk JP") -> Abdul | W38: =IFERROR(VLOOKUP(H38,jp!AL:AP,5,0),0) -> 3
A39: 0001887881_16AKWY1008 | B39: TOKO WIWIN | F39: 390345.64 | H39: =A39 -> 0001887881_16AKWY1008 | I39: =B39 -> TOKO WIWIN | J39: =C39 -> 0 | K39: =D39 -> 0 | L39: =E39 -> 0 | M39: =F39 -> 390345.64 | N39: =J39*$N$4 -> 0 | O39: =K39*$O$4 -> 0 | P39: =L39*$P$4 -> 0 | Q39: =M39*$Q$4 -> 412205 | R39: =IF(N39>Treshold!$D$4,1,0) -> 0 | S39: =IF(O39>Treshold!$D$5,1,0) -> 0 | T39: =IF(P39>Treshold!$D$6,1,0) -> 0 | U39: =IF(Q39>Treshold!$D$7,1,0) -> 1 | V39: =IFERROR(VLOOKUP(H39,jp!AL:AP,4,0),"Belum Masuk JP") -> Watinah Amalia | W39: =IFERROR(VLOOKUP(H39,jp!AL:AP,5,0),0) -> 1
A40: 0001887881_16AKXC1010 | B40: Toko Rizky Jaya | D40: 246745.27 | E40: 317791.67 | H40: =A40 -> 0001887881_16AKXC1010 | I40: =B40 -> Toko Rizky Jaya | J40: =C40 -> 0 | K40: =D40 -> 246745.27 | L40: =E40 -> 317791.67 | M40: =F40 -> 0 | N40: =J40*$N$4 -> 0 | O40: =K40*$O$4 -> 260563 | P40: =L40*$P$4 -> 335588 | Q40: =M40*$Q$4 -> 0 | R40: =IF(N40>Treshold!$D$4,1,0) -> 0 | S40: =IF(O40>Treshold!$D$5,1,0) -> 1 | T40: =IF(P40>Treshold!$D$6,1,0) -> 1 | U40: =IF(Q40>Treshold!$D$7,1,0) -> 0 | V40: =IFERROR(VLOOKUP(H40,jp!AL:AP,4,0),"Belum Masuk JP") -> Tuan Suhanda | W40: =IFERROR(VLOOKUP(H40,jp!AL:AP,5,0),0) -> 3
...

Sheet jp
A1: File Code | B1: Geo Tree 1 Code | C1: Geo Tree 1 Name | D1: Geo Tree 2 Code | E1: Geo Tree 2 Name | F1: Geo Tree 4 Code | G1: Geo Tree 4 Name | H1: Geo Tree 4 Code | I1: Geo Tree 4 Name | J1: Geo Tree 5 Code | K1: Geo Tree 5 Name | L1: Geo Tree 6 Code | M1: Geo Tree 6 Name | N1: Distributor Code | O1: Distributor Name | P1: Salesman Code | Q1: Salesman Name | R1: Salesman Type | S1: Freq Week | T1: Call Plan ID | U1: Call Plan Name | V1: Visit Day | W1: Call Sequence | X1: Customer Code | Y1: Customer Code Key | Z1: Customer Name | AA1: Channel Code | AB1: Channel Name | AC1: Sub Channel Code | AD1: Sub Channel Name | AE1: Customer Category | AF1: Customer Address | AG1: Target | AH1: Latitude | AI1: Longitude | AJ1: Kabupaten
A2: TJourneyPlan | B2: R21 | C2: ID GREATER JAKARTA REGION | D2: R21 | E2: ID GREATER JAKARTA REGION | F2: R21-05 | G2: ID Bekasi Area | H2: R21-05 | I2: ID Bekasi Area | J2: R21-05-01 | K2: ID Bekasi Area | N2: 1887881 | O2: PT Bintang Bunut | P2: MTS001 | Q2: Ajeng | R2: Taking Order | S2: W | T2: MTS001 | U2: MTS001 | V2: 7 | W2: 480 | X2: 150062 | Y2: 1887881#150062 | Z2: NAGA TAMBUN | AA2: 1502 | AB2: Supermarket | AC2: 150202 | AD2: Supermarket Local | AE2: Uncategorized | AF2: Jl Diponegoro No85 RT5RW1 Setiamekar Kec, Tambun Sel Kabupaten Bekasi Jawa Barat 17510 I, ndonesia | AG2: 0 | AH2: -6.2577752 | AI2: 107.05041
A3: TJourneyPlan | B3: R21 | C3: ID GREATER JAKARTA REGION | D3: R21 | E3: ID GREATER JAKARTA REGION | F3: R21-05 | G3: ID Bekasi Area | H3: R21-05 | I3: ID Bekasi Area | J3: R21-05-01 | K3: ID Bekasi Area | N3: 1887881 | O3: PT Bintang Bunut | P3: MTS001 | Q3: Ajeng | R3: Taking Order | S3: W | T3: MTS001 | U3: MTS001 | V3: 7 | W3: 490 | X3: 150064 | Y3: 1887881#150064 | Z3: NAGA PONDOK GEDE | AA3: 1502 | AB3: Supermarket | AC3: 150202 | AD3: Supermarket Local | AE3: Uncategorized | AF3: Plazza pondok gede 2 lantai 2 RT001RW001 Jati, waringin Kec Pd Gede Kota Bks Jawa Barat 1741, 1 Indonesia | AG3: 0 | AH3: -6.2847525 | AI3: 106.91186 | AM3: Salesman Code | AN3: (Multiple Items)
A4: TJourneyPlan | B4: R21 | C4: ID GREATER JAKARTA REGION | D4: R21 | E4: ID GREATER JAKARTA REGION | F4: R21-05 | G4: ID Bekasi Area | H4: R21-05 | I4: ID Bekasi Area | J4: R21-05-01 | K4: ID Bekasi Area | N4: 1887881 | O4: PT Bintang Bunut | P4: MTS001 | Q4: Ajeng | R4: Taking Order | S4: W | T4: MTS001 | U4: MTS001 | V4: 1 | W4: 170 | X4: 150064 | Y4: 1887881#150064 | Z4: NAGA PONDOK GEDE | AA4: 1502 | AB4: Supermarket | AC4: 150202 | AD4: Supermarket Local | AE4: Uncategorized | AF4: Plazza pondok gede 2 lantai 2 RT001RW001 Jati, waringin Kec Pd Gede Kota Bks Jawa Barat 1741, 1 Indonesia | AG4: 0 | AH4: -6.2847525 | AI4: 106.91186 | AM4: Channel Name | AN4: Provision
A5: TJourneyPlan | B5: R21 | C5: ID GREATER JAKARTA REGION | D5: R21 | E5: ID GREATER JAKARTA REGION | F5: R21-05 | G5: ID Bekasi Area | H5: R21-05 | I5: ID Bekasi Area | J5: R21-05-01 | K5: ID Bekasi Area | N5: 1887881 | O5: PT Bintang Bunut | P5: MTS001 | Q5: Ajeng | R5: Taking Order | S5: W | T5: MTS001 | U5: MTS001 | V5: 7 | W5: 500 | X5: 150066 | Y5: 1887881#150066 | Z5: NAGA CIRACAS | AA5: 1502 | AB5: Supermarket | AC5: 150202 | AD5: Supermarket Local | AE5: Uncategorized | AF5: Jl Raya Bogor KM26 No20 RT1RW8 Ciracas Ke, c Ciracas Kota Jakarta Timur Daerah Khusus Ibuk, ota Jakarta 13740 Indonesia | AG5: 0 | AH5: -6.3309713 | AI5: 106.86763 | AL5: TARIK BAWAH TIAP REFRESH
A6: TJourneyPlan | B6: R21 | C6: ID GREATER JAKARTA REGION | D6: R21 | E6: ID GREATER JAKARTA REGION | F6: R21-05 | G6: ID Bekasi Area | H6: R21-05 | I6: ID Bekasi Area | J6: R21-05-01 | K6: ID Bekasi Area | N6: 1887881 | O6: PT Bintang Bunut | P6: MTS001 | Q6: Ajeng | R6: Taking Order | S6: W | T6: MTS001 | U6: MTS001 | V6: 7 | W6: 510 | X6: 150094 | Y6: 1887881#150094 | Z6: NAGA CIKARANG | AA6: 1502 | AB6: Supermarket | AC6: 150202 | AD6: Supermarket Local | AE6: Uncategorized | AF6: Jl RE Martadinata No17 Cikarang Kota Kec Cik, arang Utara Kabupaten Bekasi Jawa Barat 17530 I, ndonesia | AG6: 0 | AH6: -6.2588518 | AI6: 107.14772 | AL6: Comp Cust Code | AM6: Customer Code | AN6: Customer Name | AO6: Salesman Name | AP6: Visit Day
A7: TJourneyPlan | B7: R21 | C7: ID GREATER JAKARTA REGION | D7: R21 | E7: ID GREATER JAKARTA REGION | F7: R21-05 | G7: ID Bekasi Area | H7: R21-05 | I7: ID Bekasi Area | J7: R21-05-01 | K7: ID Bekasi Area | N7: 1887881 | O7: PT Bintang Bunut | P7: MTS001 | Q7: Ajeng | R7: Taking Order | S7: W | T7: MTS001 | U7: MTS001 | V7: 7 | W7: 520 | X7: 15060 | Y7: 1887881#15060 | Z7: NAGA PEKAYON | AA7: 1502 | AB7: Supermarket | AC7: 150202 | AD7: Supermarket Local | AE7: Uncategorized | AF7: Jl Raya Pekayon No177 RT001RW020 Pekayon Ja, ya Kec Bekasi Sel Kota Bks Jawa Barat 17148, Indonesia | AG7: 0 | AH7: -6.2642013 | AI7: 106.98721 | AL7: ="0001887881_"&AM7 -> 0001887881_10014 | AM7: 10014 | AN7: BINTANG | AO7: Tuan Suhanda | AP7: 2
A8: TJourneyPlan | B8: R21 | C8: ID GREATER JAKARTA REGION | D8: R21 | E8: ID GREATER JAKARTA REGION | F8: R21-05 | G8: ID Bekasi Area | H8: R21-05 | I8: ID Bekasi Area | J8: R21-05-01 | K8: ID Bekasi Area | N8: 1887881 | O8: PT Bintang Bunut | P8: MTS001 | Q8: Ajeng | R8: Taking Order | S8: W | T8: MTS001 | U8: MTS001 | V8: 7 | W8: 530 | X8: 15061 | Y8: 1887881#15061 | Z8: NAGA KRANJI | AA8: 1502 | AB8: Supermarket | AC8: 150202 | AD8: Supermarket Local | AE8: Uncategorized | AF8: JL JEND SUDIRMAN NO 57 | AG8: 0 | AH8: -6.22512 | AI8: 106.97969 | AL8: ="0001887881_"&AM8 -> 0001887881_10024 | AM8: 10024 | AN8: SURYA GROUP III | AO8: Tuan Suhanda | AP8: 6
A9: TJourneyPlan | B9: R21 | C9: ID GREATER JAKARTA REGION | D9: R21 | E9: ID GREATER JAKARTA REGION | F9: R21-05 | G9: ID Bekasi Area | H9: R21-05 | I9: ID Bekasi Area | J9: R21-05-01 | K9: ID Bekasi Area | N9: 1887881 | O9: PT Bintang Bunut | P9: MTS001 | Q9: Ajeng | R9: Taking Order | S9: W | T9: MTS001 | U9: MTS001 | V9: 7 | W9: 540 | X9: 15063 | Y9: 1887881#15063 | Z9: NAGA PONDOK UNGU | AA9: 1502 | AB9: Supermarket | AC9: 150202 | AD9: Supermarket Local | AE9: Uncategorized | AF9: Jl Sultan Agung No18 RT007RW006 Medan Satri, a Kecamatan Medan Satria Kota Bks Jawa Barat 17, 132 Indonesia | AG9: 0 | AH9: -6.1965387 | AI9: 106.97442 | AL9: ="0001887881_"&AM9 -> 0001887881_10025 | AM9: 10025 | AN9: SURYA GROUP I | AO9: Tuan Suhanda | AP9: 6
A10: TJourneyPlan | B10: R21 | C10: ID GREATER JAKARTA REGION | D10: R21 | E10: ID GREATER JAKARTA REGION | F10: R21-05 | G10: ID Bekasi Area | H10: R21-05 | I10: ID Bekasi Area | J10: R21-05-01 | K10: ID Bekasi Area | N10: 1887881 | O10: PT Bintang Bunut | P10: MTS001 | Q10: Ajeng | R10: Taking Order | S10: W | T10: MTS001 | U10: MTS001 | V10: 7 | W10: 550 | X10: 15065 | Y10: 1887881#15065 | Z10: NAGA JATI WARINGIN | AA10: 1502 | AB10: Supermarket | AC10: 150202 | AD10: Supermarket Local | AE10: Uncategorized | AF10: Jl Raya Jatiwaringin No91 Jatiwaringin Kec Pd, Gede Kota Jakarta Timur Daerah Khusus Ibukota, Jakarta 17411 Indonesia | AG10: 0 | AH10: -6.2483851 | AI10: 106.90785 | AL10: ="0001887881_"&AM10 -> 0001887881_10032 | AM10: 10032 | AN10: TOKO KURNIA | AO10: Tuan Suhanda | AP10: 1
A11: TJourneyPlan | B11: R21 | C11: ID GREATER JAKARTA REGION | D11: R21 | E11: ID GREATER JAKARTA REGION | F11: R21-05 | G11: ID Bekasi Area | H11: R21-05 | I11: ID Bekasi Area | J11: R21-05-01 | K11: ID Bekasi Area | N11: 1887881 | O11: PT Bintang Bunut | P11: MTS001 | Q11: Ajeng | R11: Taking Order | S11: W | T11: MTS001 | U11: MTS001 | V11: 7 | W11: 560 | X11: 15067 | Y11: 1887881#15067 | Z11: NAGA JATI ASIH | AA11: 1502 | AB11: Supermarket | AC11: 150202 | AD11: Supermarket Local | AE11: Uncategorized | AF11: Jl Raya Jatiasih No1 RT005RW004 Jatiasih K, ec Jatiasih Kota Bks Jawa Barat 17423 Indonesi, a | AG11: 0 | AH11: -6.2942705 | AI11: 106.96488 | AL11: ="0001887881_"&AM11 -> 0001887881_10042 | AM11: 10042 | AN11: TOKO AUREL | AO11: Tuan Suhanda | AP11: 1
A12: TJourneyPlan | B12: R21 | C12: ID GREATER JAKARTA REGION | D12: R21 | E12: ID GREATER JAKARTA REGION | F12: R21-05 | G12: ID Bekasi Area | H12: R21-05 | I12: ID Bekasi Area | J12: R21-05-01 | K12: ID Bekasi Area | N12: 1887881 | O12: PT Bintang Bunut | P12: MTS001 | Q12: Ajeng | R12: Taking Order | S12: W | T12: MTS001 | U12: MTS001 | V12: 7 | W12: 570 | X12: 151182 | Y12: 1887881#151182 | Z12: NAGA WISMA ASRI | AA12: 1502 | AB12: Supermarket | AC12: 150202 | AD12: Supermarket Local | AE12: Uncategorized | AF12: GF Naga Wisma ASRI JL Perjuangan Raya Harapa, n Baru 88 Perwira 17123 Bekasi Jawa Barat, RT001RW008 Harapan Baru Bekasi Utara Bekasi | AG12: 0 | AH12: -6.2212808 | AI12: 107.01864 | AL12: ="0001887881_"&AM12 -> 0001887881_10056 | AM12: 10056 | AN12: TOKO PRIMA JAYA 6 | AO12: Tuan Suhanda | AP12: 3
A13: TJourneyPlan | B13: R21 | C13: ID GREATER JAKARTA REGION | D13: R21 | E13: ID GREATER JAKARTA REGION | F13: R21-05 | G13: ID Bekasi Area | H13: R21-05 | I13: ID Bekasi Area | J13: R21-05-01 | K13: ID Bekasi Area | N13: 1887881 | O13: PT Bintang Bunut | P13: MTS001 | Q13: Ajeng | R13: Taking Order | S13: W | T13: MTS001 | U13: MTS001 | V13: 7 | W13: 110 | X13: 35352 | Y13: 1887881#35352 | Z13: HOLLAND BAKERY | AA13: 1715 | AB13: Institution and Entertaiment | AC13: 171504 | AD13: Horeca | AE13: Uncategorized | AF13: Jl Karang Bolong Raya No1 RT6RW4 Ancol, kec Pademangan Jkt Utara Daerah Khusus Ibukota | AG13: 0 | AH13: -6.125759 | AI13: 106.81555 | AL13: ="0001887881_"&AM13 -> 0001887881_10061 | AM13: 10061 | AN13: TOKO JAYA BARU | AO13: Tuan Suhanda | AP13: 1
